{
  "seed": 60,
  "generator": "spe_sujet2_auto_07_question",
  "success": false,
  "error": "1 validation error for Fraction\nq\n  Value error, Denominator cannot be zero [type=value_error, input_value=Integer(n=0), input_type=Integer]\n    For further information visit https://errors.pydantic.dev/2.8/v/value_error",
  "error_type": "ValidationError",
  "traceback": "Traceback (most recent call last):\n  File \"/Users/selim/madles/pca-mathspm/src/build_questions.py\", line 112, in generate_question\n    module = load_generator_module(generator_file)\n  File \"/Users/selim/madles/pca-mathspm/src/build_questions.py\", line 46, in load_generator_module\n    spec.loader.exec_module(module)\n    ~~~~~~~~~~~~~~~~~~~~~~~^^^^^^^^\n  File \"<frozen importlib._bootstrap_external>\", line 1026, in exec_module\n  File \"<frozen importlib._bootstrap>\", line 488, in _call_with_frames_removed\n  File \"/Users/selim/madles/pca-mathspm/src/sujets0/generators/spe_sujet2_auto_07_question.py\", line 67, in <module>\n    \"simplified_latex\": answer[\"maths_object\"].simplified().latex(),\n                        ~~~~~~~~~~~~~~~~~~~~~~~~~~~~~~~~~^^\n  File \"/Users/selim/madles/pca-teachers/src/teachers/maths.py\", line 651, in simplified\n    return Fraction(p=p, q=q)\n  File \"/Users/selim/.pyenv/versions/3.13.5/lib/python3.13/site-packages/pydantic/main.py\", line 193, in __init__\n    self.__pydantic_validator__.validate_python(data, self_instance=self)\n    ~~~~~~~~~~~~~~~~~~~~~~~~~~~~~~~~~~~~~~~~~~~^^^^^^^^^^^^^^^^^^^^^^^^^^\npydantic_core._pydantic_core.ValidationError: 1 validation error for Fraction\nq\n  Value error, Denominator cannot be zero [type=value_error, input_value=Integer(n=0), input_type=Integer]\n    For further information visit https://errors.pydantic.dev/2.8/v/value_error\n",
  "stdout": "",
  "stderr": ""
}